<?xml version="1.0" ?>
<!-- =================================================================================== -->
<!-- |    This document was autogenerated by xacro from donaxi_urdf.xacro              | -->
<!-- |    EDITING THIS FILE BY HAND IS NOT RECOMMENDED                                 | -->
<!-- =================================================================================== -->
<robot name="donaxi" xmlns:xacro="http://ros.org/wiki/xacro">
  <!-- Define a number of dimensions using properties -->
  <!-- Include all component files -->
  <material name="Black">
    <color rgba="0.2 0.2 0.2 1.0"/>
  </material>
  <material name="TransparentBlack">
    <color rgba="0.2 0.2 0.2 0.8"/>
  </material>
  <material name="Orange">
    <color rgba="1.0  0.55 0.0 1.0"/>
  </material>
  <material name="Grey">
    <color rgba="0.7 0.7 0.7 1.0"/>
  </material>
  <material name="DarkGrey">
    <color rgba="0.3 0.3 0.3 1.0"/>
  </material>
  <material name="Red">
    <color rgba="0.8 0.0 0.0 1.0"/>
  </material>
  <material name="White">
    <color rgba="1.0 1.0 1.0 1.0"/>
  </material>
  <material name="OffWhite">
    <color rgba="0.8 0.8 0.8 1.0"/>
  </material>
  <material name="Blue">
    <color rgba="0.0 0.0 0.8 1.0"/>
  </material>
  <material name="Green">
    <color rgba="0.0 0.8 0.0 1.0"/>
  </material>
  <material name="TransparentGreen">
    <color rgba="0.0 0.8 0.0 0.5"/>
  </material>
  <link name="base_footprint">
    <visual>
      <origin rpy="0 0 0" xyz="0 0 0"/>
      <geometry>
        <box size="0.05 0.05 0.001"/>
      </geometry>
      <material name="TransparentGreen"/>
    </visual>
  </link>
  <joint name="base_joint" type="fixed">
    <origin rpy="0 0 0" xyz="0 0 0.13425"/>
    <parent link="base_footprint"/>
    <child link="base_link"/>
  </joint>
  <joint name="base_l_wheel_joint" type="continuous">
    <axis xyz="0 0 1"/>
    <limit effort="100" velocity="100"/>
    <safety_controller k_velocity="10"/>
    <origin rpy="1.570795 0 0" xyz="0.2 0.2 -0.03207"/>
    <parent link="base_link"/>
    <child link="base_l_wheel_link"/>
  </joint>
  <link name="base_l_wheel_link">
    <visual>
      <origin rpy="0 0 0" xyz="0 0 0"/>
      <geometry>
        <cylinder length="0.05" radius="0.11"/>
      </geometry>
      <material name="Black"/>
    </visual>
  </link>
  <joint name="base_r_wheel_joint" type="continuous">
    <axis xyz="0 0 1"/>
    <limit effort="100" velocity="100"/>
    <safety_controller k_velocity="10"/>
    <origin rpy="-1.570795 0 0" xyz="0.2 -0.2 -0.03207"/>
    <parent link="base_link"/>
    <child link="base_r_wheel_link"/>
  </joint>
  <link name="base_r_wheel_link">
    <visual>
      <origin rpy="0 0 0" xyz="0 0 0"/>
      <geometry>
        <cylinder length="0.05" radius="0.11"/>
      </geometry>
      <material name="Black"/>
    </visual>
  </link>
  <joint name="base_l2_wheel2_joint" type="continuous">
    <axis xyz="0 0 1"/>
    <limit effort="100" velocity="100"/>
    <safety_controller k_velocity="10"/>
    <origin rpy="1.570795 0 0" xyz="-0.2 0.2 -0.03207"/>
    <parent link="base_link"/>
    <child link="base_l2_wheel2_link"/>
  </joint>
  <link name="base_l2_wheel2_link">
    <visual>
      <origin rpy="0 0 0" xyz="0 0 0"/>
      <geometry>
        <cylinder length="0.05" radius="0.11"/>
      </geometry>
      <material name="Black"/>
    </visual>
  </link>
  <joint name="base_r2_wheel2_joint" type="continuous">
    <axis xyz="0 0 1"/>
    <limit effort="100" velocity="100"/>
    <safety_controller k_velocity="10"/>
    <origin rpy="-1.570795 0 0" xyz="-0.2 -0.2 -0.03207"/>
    <parent link="base_link"/>
    <child link="base_r2_wheel2_link"/>
  </joint>
  <link name="base_r2_wheel2_link">
    <visual>
      <origin rpy="0 0 0" xyz="0 0 0"/>
      <geometry>
        <cylinder length="0.05" radius="0.11"/>
      </geometry>
      <material name="Black"/>
    </visual>
  </link>
  <!-- Add the base and wheels -->
  <link name="base_link">
    <visual>
      <origin rpy="0 0 1.570795 " xyz="0 0 0"/>
      <geometry>
        <mesh filename="package://donaxi_description/meshes/Base.stl" scale="0.001 0.001 0.001"/>
      </geometry>
      <material name="Black"/>
    </visual>
    <collision>
      <origin rpy="0 0 0" xyz="0 0 0"/>
      <geometry>
        <box size="0.7 0.45 0.1585"/>
      </geometry>
    </collision>
  </link>
  <!-- Add the riel -->
  <joint name="base_riel_joint" type="fixed">
    <origin rpy="0 0 0" xyz="0.0 0.0 0.53"/>
    <parent link="base_link"/>
    <child link="riel_link"/>
  </joint>
  <link name="riel_link">
    <visual>
      <origin rpy="0 0 -1.570795" xyz="0 0 0"/>
      <geometry>
        <mesh filename="package://donaxi_description/meshes/Riel_FA.stl" scale="1 1 1"/>
      </geometry>
      <material name="Black"/>
    </visual>
    <collision>
      <origin rpy="0 0 0" xyz="0 0 0"/>
      <geometry>
        <box size="0.025 0.025 0.885"/>
      </geometry>
    </collision>
  </link>
  <!-- Add the central frame -->
  <joint name="riel_central_frame_joint" type="prismatic">
    <limit effort="1000.0" lower="-0.5" upper="0.05" velocity="0.1"/>
    <axis xyz="0 0 1"/>
    <origin rpy="0 0 0" xyz="0.04 -0.24 0.35"/>
    <parent link="riel_link"/>
    <child link="central_frame_link"/>
  </joint>
  <link name="central_frame_link">
    <visual>
      <origin rpy="0 0 1.570795" xyz="0 0 0"/>
      <geometry>
        <mesh filename="package://donaxi_description/meshes/Central_Frame.stl" scale="1 1 1"/>
      </geometry>
      <material name="DarkGrey"/>
    </visual>
    <collision>
      <origin rpy="0 0 0" xyz="-0.01 0.24 0.115"/>
      <geometry>
        <box size="0.02 0.48 0.23"/>
      </geometry>
    </collision>
  </link>
  <!-- Add the kinect camera -->
  <joint name="central_frame_kinect_joint" type="fixed">
    <origin rpy="0 0 0" xyz="-0.01 0.23 0.033"/>
    <parent link="central_frame_link"/>
    <child link="kinect_link"/>
  </joint>
  <link name="kinect_link">
    <visual>
      <origin rpy="0 0 -1.570795" xyz="0.0 0 0"/>
      <geometry>
        <mesh filename="package://donaxi_description/meshes/Kinect.stl" scale="1 1 1"/>
      </geometry>
      <material name="DarkGrey"/>
    </visual>
    <collision>
      <origin rpy="0 0 -1.570795" xyz="0 0.0 0.0"/>
      <geometry>
        <box size="0.3 0.1 0.08"/>
      </geometry>
    </collision>
  </link>
  <joint name="kinect_depth_joint" type="fixed">
    <origin rpy="0 1.570795 0" xyz="0.09198 0.0 0.04319"/>
    <parent link="kinect_link"/>
    <child link="kinect_depth_frame"/>
  </joint>
  <link name="kinect_depth_frame">
    <inertial>
      <mass value="0.000001"/>
      <origin xyz="0 0 0"/>
      <inertia ixx="0.0001" ixy="0.0" ixz="0.0" iyy="0.0001" iyz="0.0" izz="0.0001"/>
    </inertial>
  </link>
  <!-- Add the neck and the head -->
  <joint name="head_base_joint" type="fixed">
    <origin rpy="0 0 3.14159" xyz="0.0 0.0 0.60325"/>
    <parent link="riel_link"/>
    <child link="head_base_link"/>
  </joint>
  <link name="head_base_link">
    <origin rpy="0 0 0" xyz="0 0 0"/>
    <inertial>
      <mass value="0.00001"/>
      <inertia ixx="1.0" ixy="0.0" ixz="0.0" iyy="1.0" iyz="0.0" izz="1.0"/>
    </inertial>
    <visual>
      <origin rpy="0 0 0" xyz="0 0 0 "/>
      <geometry>
        <cylinder length="0.00001" radius="0.01"/>
      </geometry>
    </visual>
    <collision>
      <origin rpy="0 0 0" xyz="0 0 0 "/>
      <geometry>
        <cylinder length="0.00001" radius="0.01"/>
      </geometry>
    </collision>
  </link>
  <joint name="head_pan_servo_joint" type="fixed">
    <origin rpy="1.570795 0 -1.570795" xyz="-0.012 0 0.0175"/>
    <parent link="head_base_link"/>
    <child link="head_pan_servo_link"/>
  </joint>
  <link name="head_pan_servo_link">
    <inertial>
      <mass value="0.00001"/>
      <origin xyz="0 0 0"/>
      <inertia ixx="1.0" ixy="0.0" ixz="0.0" iyy="1.0" iyz="0.0" izz="1.0"/>
    </inertial>
    <visual>
      <origin rpy="0 0 0" xyz="0 0 0"/>
      <geometry>
        <box size="0.0385 0.035 0.049"/>
      </geometry>
      <material name="Black"/>
    </visual>
    <collision>
      <origin rpy="0 0 0" xyz="0 0 -0.01241"/>
      <geometry>
        <box size="0.0385 0.035 0.049"/>
      </geometry>
    </collision>
  </link>
  <joint name="head_pan_joint" type="revolute">
    <origin rpy="-1.570795 1.570795 3.14159" xyz="0 0.0225 0.012"/>
    <axis xyz="0 0 -1"/>
    <parent link="head_pan_servo_link"/>
    <limit effort="1.0" lower="-2.53" upper="2.53" velocity="1.571"/>
    <child link="head_pan_bracket_link"/>
  </joint>
  <link name="head_pan_bracket_link">
    <inertial>
      <mass value="0.00001"/>
      <origin xyz="0 0 0"/>
      <inertia ixx="1.0" ixy="0.0" ixz="0.0" iyy="1.0" iyz="0.0" izz="1.0"/>
    </inertial>
    <visual>
      <origin rpy="0 0 0" xyz="0 0 0 "/>
      <geometry>
        <box size="0.025 0.038 0.009"/>
      </geometry>
      <material name="DarkGrey"/>
    </visual>
    <collision>
      <origin rpy="0 0 0" xyz="0 0 0"/>
      <geometry>
        <box size="0.025 0.038 0.009"/>
      </geometry>
    </collision>
  </link>
  <joint name="head_tilt_servo_joint" type="fixed">
    <origin rpy="0 3.14159 0" xyz="0 0 -0.031"/>
    <parent link="head_pan_bracket_link"/>
    <child link="head_tilt_servo_link"/>
  </joint>
  <link name="head_tilt_servo_link">
    <inertial>
      <mass value="0.00001"/>
      <origin xyz="0 0 0"/>
      <inertia ixx="1.0" ixy="0.0" ixz="0.0" iyy="1.0" iyz="0.0" izz="1.0"/>
    </inertial>
    <visual>
      <origin rpy="0 0 0" xyz="0 0 0"/>
      <geometry>
        <box size="0.0385 0.035 0.049"/>
      </geometry>
      <material name="Black"/>
    </visual>
    <collision>
      <origin rpy="0 0 0" xyz="0 0 -0.01241"/>
      <geometry>
        <box size="0.0385 0.035 0.049"/>
      </geometry>
    </collision>
  </link>
  <joint name="head_tilt_joint" type="revolute">
    <origin rpy="0 0 0" xyz="0 0 0.025"/>
    <axis xyz="0 1 0"/>
    <parent link="head_tilt_servo_link"/>
    <limit effort="1.0" lower="-2.53" upper="2.53" velocity="1.571"/>
    <child link="head_tilt_bracket_link"/>
  </joint>
  <link name="head_tilt_bracket_link">
    <inertial>
      <mass value="0.00001"/>
      <origin xyz="0 0 0"/>
      <inertia ixx="1.0" ixy="0.0" ixz="0.0" iyy="1.0" iyz="0.0" izz="1.0"/>
    </inertial>
    <visual>
      <origin rpy="0 0 0" xyz="0 0 0 "/>
      <geometry>
        <box size="0.0245 0.038 0.048"/>
      </geometry>
      <material name="DarkGrey"/>
    </visual>
    <collision>
      <origin rpy="0 0 0" xyz="0 0 0"/>
      <geometry>
        <box size="0.0245 0.038 0.048"/>
      </geometry>
    </collision>
  </link>
  <joint name="head_tilt_bracket_kinect_top_joint" type="fixed">
    <origin rpy="0 0 0" xyz="0.0 0.0 0.0345"/>
    <parent link="head_tilt_bracket_link"/>
    <child link="kinect_top_link"/>
  </joint>
  <link name="kinect_top_link">
    <visual>
      <origin rpy="0 0 -1.570795" xyz="0.0 0 0"/>
      <geometry>
        <mesh filename="package://donaxi_description/meshes/Kinect.stl" scale="1 1 1"/>
      </geometry>
      <material name="DarkGrey"/>
    </visual>
    <collision>
      <origin rpy="0 0 -1.570795" xyz="0 0.0 0.0"/>
      <geometry>
        <box size="0.3 0.1 0.08"/>
      </geometry>
    </collision>
  </link>
  <joint name="kinect_top_depth_joint" type="fixed">
    <origin rpy="0 0 0" xyz="0.09198 0.0 0.04319"/>
    <parent link="kinect_top_link"/>
    <child link="kinect_top_depth_frame"/>
  </joint>
  <link name="kinect_top_depth_frame">
    <inertial>
      <mass value="0.000001"/>
      <origin xyz="0 0 0"/>
      <inertia ixx="0.0001" ixy="0.0" ixz="0.0" iyy="0.0001" iyz="0.0" izz="0.0001"/>
    </inertial>
  </link>
  <!-- Add the right arm -->
  <joint name="right_arm_base_joint" type="fixed">
    <origin rpy="1.570795 3.14159 0" xyz="-0.07184 -0.17402 -0.04902"/>
    <parent link="kinect_depth_frame"/>
    <child link="right_arm_base_link"/>
  </joint>
  <link name="right_arm_base_link">
    <origin rpy="0 0 0" xyz="0 0 0"/>
    <inertial>
      <mass value="0.00001"/>
      <inertia ixx="1.0" ixy="0.0" ixz="0.0" iyy="1.0" iyz="0.0" izz="1.0"/>
    </inertial>
    <visual>
      <origin rpy="0 0 0" xyz="0 0 0 "/>
      <geometry>
        <cylinder length="0.00001" radius="0.01"/>
      </geometry>
    </visual>
    <collision>
      <origin rpy="0 0 0" xyz="0 0 0 "/>
      <geometry>
        <cylinder length="0.00001" radius="0.01"/>
      </geometry>
    </collision>
  </link>
  <joint name="servo_1_joint" type="fixed">
    <origin rpy="0 0 0" xyz="0 0 0"/>
    <parent link="right_arm_base_link"/>
    <child link="servo_1_link"/>
  </joint>
  <link name="servo_1_link">
    <inertial>
      <mass value="0.00001"/>
      <origin xyz="0 0 0"/>
      <inertia ixx="1.0" ixy="0.0" ixz="0.0" iyy="1.0" iyz="0.0" izz="1.0"/>
    </inertial>
    <visual>
      <origin rpy="0 0 3.14159" xyz="0.0196 0.0506 -0.046"/>
      <geometry>
        <mesh filename="package://donaxi_description/meshes/EX106.stl" scale="1 1 1"/>
      </geometry>
      <material name="DarkGrey"/>
    </visual>
    <collision>
      <origin rpy="0 0 0" xyz="0.0196 0.0506 -0.046"/>
      <geometry>
        <box size="0.046 0.0392 0.0651"/>
      </geometry>
    </collision>
  </link>
  <joint name="link_1_joint" type="revolute">
    <axis xyz="0 0 -1"/>
    <axis xyz="0 0 1"/>
    <origin rpy="0 0 0" xyz="0 0 0.05"/>
    <limit effort="1.0" lower="-1.5" upper="1.0" velocity="3.14"/>
    <parent link="servo_1_link"/>
    <child link="link_1_link"/>
  </joint>
  <link name="link_1_link">
    <visual>
      <origin rpy="0 0 0" xyz="0 0 0 "/>
      <geometry>
        <mesh filename="package://donaxi_description/meshes/Shoulder.stl" scale="1 1 1"/>
      </geometry>
      <material name="Black"/>
    </visual>
  </link>
  <joint name="servo_2_joint" type="revolute">
    <origin rpy="0 -1.570795 1.570795" xyz="0 -0.0196 0.08477"/>
    <axis xyz="0 0 -1"/>
    <limit effort="1.0" lower="-0.18" upper="1.0" velocity="3.14"/>
    <parent link="link_1_link"/>
    <child link="servo_2_link"/>
  </joint>
  <link name="servo_2_link">
    <inertial>
      <mass value="0.00001"/>
      <origin xyz="0 0 0"/>
      <inertia ixx="1.0" ixy="0.0" ixz="0.0" iyy="1.0" iyz="0.0" izz="1.0"/>
    </inertial>
    <visual>
      <origin rpy="0 0 3.14159" xyz="0.0196 0.0506 -0.046"/>
      <geometry>
        <mesh filename="package://donaxi_description/meshes/EX106.stl" scale="1 1 1"/>
      </geometry>
      <material name="DarkGrey"/>
    </visual>
    <collision>
      <origin rpy="0 0 0" xyz="0.0196 0.0506 -0.046"/>
      <geometry>
        <box size="0.046 0.0392 0.0651"/>
      </geometry>
    </collision>
  </link>
  <joint name="link_2_joint" type="fixed">
    <origin rpy="-1.570795 1.570795 0" xyz="0 0.1250 -0.0215"/>
    <parent link="servo_2_link"/>
    <child link="link_2_link"/>
  </joint>
  <link name="link_2_link">
    <inertial>
      <mass value="0.00001"/>
      <origin xyz="0 0 0"/>
      <inertia ixx="1.0" ixy="0.0" ixz="0.0" iyy="1.0" iyz="0.0" izz="1.0"/>
    </inertial>
    <visual>
      <origin rpy="0 0 0" xyz="0 0 0"/>
      <geometry>
        <mesh filename="package://donaxi_description/meshes/Upper_Arm.stl" scale="1 1 1"/>
      </geometry>
      <material name="Black"/>
    </visual>
  </link>
  <joint name="servo_3_joint" type="fixed">
    <origin rpy="-1.570795 0 0" xyz="0.0 0.01443 0.1443 "/>
    <parent link="link_2_link"/>
    <child link="servo_3_link"/>
  </joint>
  <link name="servo_3_link">
    <inertial>
      <mass value="0.00001"/>
      <origin xyz="0 0 0"/>
      <inertia ixx="1.0" ixy="0.0" ixz="0.0" iyy="1.0" iyz="0.0" izz="1.0"/>
    </inertial>
    <visual>
      <origin rpy="0 0 3.14159" xyz="0.0201 0.0466 -0.041"/>
      <geometry>
        <mesh filename="package://donaxi_description/meshes/RX64.stl" scale="1 1 1"/>
      </geometry>
      <material name="DarkGrey"/>
    </visual>
    <collision>
      <origin rpy="0 0 0" xyz="0.0201 0.0466 -0.041"/>
      <geometry>
        <box size="0.041 0.0402 0.0611"/>
      </geometry>
    </collision>
  </link>
  <joint name="link_3_joint" type="revolute">
    <axis xyz="0 0 1"/>
    <axis xyz="0 0 1"/>
    <origin rpy="0 3.14159 3.14159" xyz="0 0 -0.0154"/>
    <limit effort="1.0" lower="-0.22" upper="1.5" velocity="3.14"/>
    <parent link="servo_3_link"/>
    <child link="link_3_link"/>
  </joint>
  <link name="link_3_link">
    <visual>
      <origin rpy="0 0 0" xyz="0 0 0 "/>
      <geometry>
        <mesh filename="package://donaxi_description/meshes/Elbow.stl" scale="1 1 1"/>
      </geometry>
      <material name="Black"/>
    </visual>
  </link>
  <joint name="servo_4_joint" type="fixed">
    <origin rpy="-1.570795 -1.570795 0" xyz="0.0221 0.1485 0.0 "/>
    <parent link="link_3_link"/>
    <child link="servo_4_link"/>
  </joint>
  <link name="servo_4_link">
    <inertial>
      <mass value="0.00001"/>
      <origin xyz="0 0 0"/>
      <inertia ixx="1.0" ixy="0.0" ixz="0.0" iyy="1.0" iyz="0.0" izz="1.0"/>
    </inertial>
    <visual>
      <origin rpy="0 0 3.14159" xyz="0.0201 0.0466 -0.041"/>
      <geometry>
        <mesh filename="package://donaxi_description/meshes/RX64.stl" scale="1 1 1"/>
      </geometry>
      <material name="DarkGrey"/>
    </visual>
    <collision>
      <origin rpy="0 0 0" xyz="0.0201 0.0466 -0.041"/>
      <geometry>
        <box size="0.041 0.0402 0.0611"/>
      </geometry>
    </collision>
  </link>
  <joint name="link_4_joint" type="revolute">
    <axis xyz="0 0 -1"/>
    <axis xyz="0 0 1"/>
    <origin rpy="0 0 -1.570795" xyz="0 0 0.009"/>
    <limit effort="1.0" lower="-1.45" upper="1.45" velocity="3.14"/>
    <parent link="servo_4_link"/>
    <child link="link_4_link"/>
  </joint>
  <link name="link_4_link">
    <visual>
      <origin rpy="0 0 0" xyz="0 0 0 "/>
      <geometry>
        <mesh filename="package://donaxi_description/meshes/Fourth_Link.stl" scale="1 1 1"/>
      </geometry>
      <material name="Black"/>
    </visual>
  </link>
  <joint name="servo_5_joint" type="fixed">
    <origin rpy="0 1.570795 1.570795" xyz="0.0013 0.0133 0.0589 "/>
    <parent link="link_4_link"/>
    <child link="servo_5_link"/>
  </joint>
  <link name="servo_5_link">
    <inertial>
      <mass value="0.00001"/>
      <origin xyz="0 0 0"/>
      <inertia ixx="1.0" ixy="0.0" ixz="0.0" iyy="1.0" iyz="0.0" izz="1.0"/>
    </inertial>
    <visual>
      <origin rpy="0 0 3.14159" xyz="0.0178 0.0361 -0.0355"/>
      <geometry>
        <mesh filename="package://donaxi_description/meshes/RX28.stl" scale="1 1 1"/>
      </geometry>
      <material name="DarkGrey"/>
    </visual>
    <collision>
      <origin rpy="0 0 0" xyz="0.0178 0.0361 -0.0355"/>
      <geometry>
        <box size="0.0355 0.0356 0.0506"/>
      </geometry>
    </collision>
  </link>
  <joint name="link_5_joint" type="revolute">
    <axis xyz="0 0 1"/>
    <axis xyz="0 0 1"/>
    <origin rpy="0 0 3.14159" xyz="0 -0.00235 -0.0352"/>
    <limit effort="1.0" lower="-0.23" upper="1.59" velocity="3.14"/>
    <parent link="servo_5_link"/>
    <child link="link_5_link"/>
  </joint>
  <link name="link_5_link">
    <visual>
      <origin rpy="0 0 0" xyz="-0.0025 -0.013 0 "/>
      <geometry>
        <mesh filename="package://donaxi_description/meshes/Wrist.stl" scale="1 1 1"/>
      </geometry>
      <material name="Black"/>
    </visual>
  </link>
  <joint name="link_6_joint" type="fixed">
    <origin rpy="-1.570795 1.570795 0" xyz="0.07100 0 0.03574"/>
    <parent link="link_5_link"/>
    <child link="link_6_link"/>
  </joint>
  <link name="link_6_link">
    <inertial>
      <mass value="0.00001"/>
      <origin xyz="0 0 0"/>
      <inertia ixx="1.0" ixy="0.0" ixz="0.0" iyy="1.0" iyz="0.0" izz="1.0"/>
    </inertial>
    <visual>
      <origin rpy="0 0 0" xyz="0 0 0"/>
      <geometry>
        <mesh filename="package://donaxi_description/meshes/Gripper.stl" scale="1 1 1"/>
      </geometry>
      <material name="Black"/>
    </visual>
  </link>
  <joint name="gripper_joint" type="fixed">
    <origin rpy="0 0 -1.570795" xyz="0.015 -0.085 -0.01825"/>
    <parent link="link_6_link"/>
    <child link="gripper_link"/>
  </joint>
  <link name="gripper_link">
    <origin rpy="0 0 0" xyz="0.0 0.0 0.0"/>
    <visual>
      <origin rpy="0 0 0" xyz="0.0 0.0 0.0"/>
      <geometry>
        <cylinder length="0.00001" radius="0.01"/>
      </geometry>
    </visual>
    <collision>
      <origin rpy="0 0 0" xyz="0.0 0.0 0.0"/>
      <geometry>
        <cylinder length="0.00001" radius="0.01"/>
      </geometry>
    </collision>
  </link>
</robot>

